Workbook

Sheet تعليمات
B2: نموذج تحديث بيانات منصة السكن الجماعي للأفراد — مدينة الرياض
B4: طريقة الاستخدام: عدِّل الأرقام في الخلايا الصفراء فقط، ثم أعد إرفاق الملف لكلود لتحديث المنصة ونشرها.
B6: دليل الألوان:
B7: ▪ خلية صفراء بنص أزرق = قيمة قابلة للتعديل.
B8: ▪ خلية خضراء فاتحة = مجموع/فحص محسوب تلقائياً — لا تعدلها.
B10: قواعد الاتساق (تتحقق منها خلايا الفحص في كل ورقة — يجب أن تظهر ✓ قبل إعادة الإرفاق):
B11: ▪ مجموع طلب القطاعات = إجمالي الطلب.
B12: ▪ الرصيد قبل سبتمبر 2025 + الإضافات الشهرية = مجموع القطاعات (رخص بناء، تشغيلية، أسرّة).
B13: ▪ «العرض» في المنصة يُشتق تلقائياً من أسرّة الرخص التشغيلية — لا يُدخل يدوياً.
B14: ▪ مجموع أنواع المخالفات = مجموع مخالفات القطاعات، ومجاميع النشاط الشهري تطابق إجماليات الرقابة.
B15: ▪ أرقام أحياء كل قطاع يجب ألا تتجاوز إجمالي قطاعها.
B17: ملاحظات:
... B20: ▪ القيم الحالية للمؤشرات تُسجَّل من داخل المنصة (زر تعديل) وتُزامَن عبر قاعدة البيانات.

Sheet الطلب
B2: الطلب على السكن الجماعي للأفراد (سرير)
B4: إجمالي الطلب | C4: 1420000
B6: القطاع | C6: الطلب
B7: قطاع الشمال | C7: 258000
B8: قطاع الشرق | C8: 331000
B9: قطاع الوسط | C9: 246000
B10: قطاع الغرب | C10: 217000
B11: قطاع الجنوب | C11: 368000
B12: المجموع (محسوب) | C12: =SUM(C7:C11) -> 1420000
B13: فحص الاتساق | C13: =IF(C12=C4,"✓ متسق مع الإجمالي","✗ لا يساوي الإجمالي") -> ✓ متسق مع الإجمالي

Sheet التراخيص
B2: التراخيص والطاقة الاستيعابية
B4: البند | C4: رخص البناء | D4: الرخص التشغيلية | E4: الأسرّة (الطاقة)
B5: الرصيد قبل سبتمبر 2025 | C5: 64 | D5: 118 | E5: 563900
B7: الإضافات الشهرية الصافية
B8: سبتمبر 2025 | C8: 3 | D8: 1 | E8: 3200
B9: أكتوبر 2025 | C9: 2 | D9: 2 | E9: 3600
B10: نوفمبر 2025 | C10: 3 | D10: 2 | E10: 4100
B11: ديسمبر 2025 | C11: 3 | D11: 2 | E11: 3900
B12: يناير 2026 | C12: 2 | D12: 1 | E12: 4200
B13: فبراير 2026 | C13: 3 | D13: 2 | E13: 4400
B14: مارس 2026 | C14: 3 | D14: 2 | E14: 4100
B15: أبريل 2026 | C15: 3 | D15: 2 | E15: 4300
B16: مايو 2026 | C16: 2 | D16: 2 | E16: 4200
B17: يونيو 2026 | C17: 3 | D17: 2 | E17: 4200
B18: يوليو 2026 | C18: 3 | D18: 2 | E18: 4100
B19: أغسطس 2026 | C19: 2 | D19: 2 | E19: 4200
B20: الإجمالي الحالي (محسوب = الرصيد + الإضافات) | C20: =C5+SUM(C8:C19) -> 96 | D20: =D5+SUM(D8:D19) -> 140 | E20: =E5+SUM(E8:E19) -> 612400
B22: الوضع الراهن حسب القطاع
B23: قطاع الشمال | C23: 22 | D23: 30 | E23: 128000
B24: قطاع الشرق | C24: 26 | D24: 34 | E24: 172400
B25: قطاع الوسط | C25: 12 | D25: 26 | E25: 96000
B26: قطاع الغرب | C26: 16 | D26: 22 | E26: 88000
B27: قطاع الجنوب | C27: 20 | D27: 28 | E27: 128000
B28: مجموع القطاعات (محسوب) | C28: =SUM(C23:C27) -> 96 | D28: =SUM(D23:D27) -> 140 | E28: =SUM(E23:E27) -> 612400
B29: فحص: مجموع القطاعات = الإجمالي الحالي | C29: =IF(C28=C20,"✓","✗") -> ✓ | D29: =IF(D28=D20,"✓","✗") -> ✓ | E29: =IF(E28=E20,"✓","✗") -> ✓
B31: هدف نسبة التغطية الاسترشادي (٪) | C31: 60

Sheet الرقابة
B2: الرقابة الميدانية (آخر 12 شهراً)
B4: القطاع | C4: المراقبون | D4: المخالفات | E4: الزيارات | F4: قرارات الإغلاق
B5: قطاع الشمال | C5: 4 | D5: 439 | E5: 3538 | F5: 15
B6: قطاع الشرق | C6: 4 | D6: 907 | E6: 4716 | F6: 27
B7: قطاع الوسط | C7: 4 | D7: 548 | E7: 3341 | F7: 19
B8: قطاع الغرب | C8: 3 | D8: 356 | E8: 2553 | F8: 12
B9: قطاع الجنوب | C9: 3 | D9: 1367 | E9: 5503 | F9: 40
B10: الإجمالي (محسوب) | C10: =SUM(C5:C9) -> 18 | D10: =SUM(D5:D9) -> 3617 | E10: =SUM(E5:E9) -> 19651 | F10: =SUM(F5:F9) -> 113
B12: معدل الامتثال في الجولات (٪) | C12: 81.6
B14: المخالفات حسب النوع
B15: الاكتظاظ وتجاوز الطاقة الاستيعابية | C15: 1121
B16: اشتراطات السلامة والحماية من الحريق | C16: 868
B17: النظافة والصحة العامة | C17: 615
B18: مزاولة النشاط بدون ترخيص | C18: 434
B19: مخالفات الكهرباء والسباكة | C19: 326
B20: التهوية والعزل غير المطابق | C20: 253
B21: مجموع الأنواع (محسوب) | C21: =SUM(C15:C20) -> 3617
B22: فحص: الأنواع = مخالفات القطاعات | C22: =IF(C21=D10,"✓","✗") -> ✓

Sheet الأحياء
B2: أبرز الأحياء — عينة مرتبطة بالخريطة (قوائم أعلى 5 تُشتق تلقائياً)
B4: الحي (مطابق للخريطة) | C4: القطاع | D4: رخص البناء | E4: الرخص التشغيلية | F4: الأسرّة | G4: المخالفات
B5: حي الملقا | C5: قطاع الشمال | D5: 6 | E5: 5 | F5: 21500 | G5: 84
B6: حي الصحافة | C6: قطاع الشمال | D6: 5 | E6: 4 | F6: 16800 | G6: 61
B7: حي حطين | C7: قطاع الشمال | D7: 4 | E7: 4 | F7: 15200 | G7: 57
B8: حي الياسمين | C8: قطاع الشمال | D8: 3 | E8: 3 | F8: 11900 | G8: 48
B9: حي النسيم الشرقي | C9: قطاع الشرق | D9: 7 | E9: 8 | F9: 34600 | G9: 216
B10: حي السلي | C10: قطاع الشرق | D10: 6 | E10: 6 | F10: 30200 | G10: 246
B11: حي النظيم | C11: قطاع الشرق | D11: 5 | E11: 5 | F11: 24800 | G11: 168
B12: حي النسيم الغربي | C12: قطاع الشرق | D12: 4 | E12: 6 | F12: 27400 | G12: 152
B13: حي منفوحة | C13: قطاع الوسط | D13: 4 | E13: 7 | F13: 23200 | G13: 187
B14: حي غبيرة | C14: قطاع الوسط | D14: 3 | E14: 5 | F14: 19400 | G14: 149
B15: حي الجرادية | C15: قطاع الوسط | D15: 2 | E15: 4 | F15: 15300 | G15: 102
B16: حي الديرة | C16: قطاع الوسط | D16: 2 | E16: 3 | F16: 11600 | G16: 76
... B24: حي بدر | C24: قطاع الجنوب | D24: 4 | E24: 4 | F24: 17600 | G24: 214
B26: قاعدة: مجموع أحياء كل قطاع ≤ إجمالي القطاع في ورقتي التراخيص والرقابة

Sheet السياق
B2: سياق تحليلي إضافي
B4: الأسرّة المشغولة (الإشغال) | C4: 561571
B5: تاريخ العرض (asOf) | C5: أغسطس 2026
B6: تاريخ اليوم للاحتساب الزمني (YYYY-MM-DD) | C6: 2026-08-11
B8: الرخص التشغيلية حسب نوع الإيواء
B9: مجمع سكني | C9: 38
B10: مبنى سكني | C10: 68
B11: كبائن متنقلة | C11: 34
B12: فحص: مجموع الأنواع = الرخص التشغيلية | C12: =IF(SUM(C9:C11)=التراخيص!D20,"✓","✗") -> ✓
B14: تركيبة الطلب
B15: الياقات الزرقاء | C15: 1164400
B16: الياقات البيضاء | C16: 255600
B17: فحص: المجموع = إجمالي الطلب | C17: =IF(C15+C16=الطلب!C4,"✓","✗") -> ✓
B19: الطلب حسب النشاط الاقتصادي
B20: التشييد والبناء | C20: 505000
B21: التجارة والتجزئة | C21: 217000
B22: الصناعة | C22: 198000
B23: الخدمات العامة | C23: 165000
B24: الضيافة والإعاشة | C24: 152000
B25: قطاعات أخرى | C25: 183000
B26: فحص: المجموع = إجمالي الطلب | C26: =IF(SUM(C20:C25)=الطلب!C4,"✓","✗") -> ✓
B28: النشاط الرقابي الشهري
B29: الشهر | C29: الزيارات | D29: المخالفات
B30: سبتمبر 2025 | C30: 1548 | D30: 292
B31: أكتوبر 2025 | C31: 1504 | D31: 288
B32: نوفمبر 2025 | C32: 1601 | D32: 293
B33: ديسمبر 2025 | C33: 1580 | D33: 279
B34: يناير 2026 | C34: 1609 | D34: 292
B35: فبراير 2026 | C35: 1654 | D35: 304
B36: مارس 2026 | C36: 1736 | D36: 316
B37: أبريل 2026 | C37: 1755 | D37: 309
B38: مايو 2026 | C38: 1800 | D38: 310
B39: يونيو 2026 | C39: 1747 | D39: 300
B40: يوليو 2026 | C40: 1558 | D40: 317
B41: أغسطس 2026 | C41: 1559 | D41: 317
B42: فحص: المجاميع = إجماليات الرقابة | C42: =IF(SUM(C30:C41)=الرقابة!E10,"✓","✗") -> ✓ | D42: =IF(SUM(D30:D41)=الرقابة!D10,"✓","✗") -> ✓
B44: التوقع المستقبلي لعجز الإيواء (سرير) — سبتمبر 2026 حتى يونيو 2027
B45: الشهر | C45: متحفظ | D45: أساسي | E45: متفائل
B46: سبتمبر 2026 | C46: 830540 | D46: 821088 | E46: 810736
B47: أكتوبر 2026 | C47: 838380 | D47: 825768 | E47: 811888
...
