Workbook

Sheet 01_تعليمات
B1: مصنّف البيانات الرئيسي V2 — لوحة معلومات السكن الجماعي للأفراد بمدينة الرياض
B2: أساس هذه النسخة | C2: مسودة البيانات الأولى المقدمة منك (riyadh-housing-dashboard-data_V1.xlsx) — كل قيمك محفوظة كما هي، مع إضافة نموذج ملكية المصادر وإصلاحات هيكلية موثقة أدناه.
B3: تاريخ الإصدار | C3: 2026-08-18
B5: نموذج ملكية المصادر (مهم)
B6: مبدأ الفصل | C6: تصنيف المؤشر في اللوحة (مثل قسم «التراخيص») لا يعني أن جهة واحدة تنتج كل بياناته — لكل بيانة أربعة أبعاد مستقلة: القسم في اللوحة، الجهة المنتجة للبيانات، المصدر، حالة المصدر.
B7: رخص البناء | C7: الجهة المصدرة: الإدارة العامة للتراخيص (حالة المصدر: أولي).
B8: الرخص التشغيلية والطاقة الاستيعابية وأنواع المساكن | C8: لا تُنسب إلى الإدارة العامة للتراخيص. الجهة المصدرة حالياً: «غير محدد / يحتاج تحديث» إلى أن تحدد الجهة الفعلية.
B9: حقول المصدر | C9: الجهة_المصدرة_للبيانات (الجهة المنتجة) · المصدر (الوثيقة/النظام) · حالة_المصدر (معتمد/أولي/يحتاج مراجعة/غير محدد) · ملاحظات_المصدر. أعمدتها برؤوس رمادية مخضرة.
B10: السجل المركزي | C10: ورقة 19_مصادر_البيانات تحصر كل مجموعة بيانات (وحتى الأعمدة داخل الورقة الواحدة عندما تختلف جهاتها، كما في 07 و08) مع جهتها وقسمها في اللوحة — هي المرجع الحاكم للملكية.
B12: إصلاحات وثّقناها على المسودة (راجعها)
B13: 1) موضع خط الأساس في 07 | C13: قيم خط الأساس الجديدة (63 / 218 / 19,485) كانت مكتوبة في أعمدة «الإضافات الشهرية» لصف الأساس بينما بقيت أعمدة «التراكمي» على القيم التجريبية القديمة — نُقلت إلى مكانها الصحيح وأُعيد بناء التراكمي كمعادلات حية.
B14: 2) صف بلا اسم في 08 | C14: وُجد صف مدرج يحمل 57 رخصة بناء فقط (به يصبح الإجمالي 165) — سُمي «غير مصنف قطاعياً» ويحتاج قرارك: توزيعه على القطاعات أو اعتماده بنداً مستقلاً.
B15: 3) قيم مخبأة قديمة | C15: بعض خلايا المشتقات كانت تحمل نتائج حسابات قديمة متضاربة (165 مقابل 166 و76) — أُعيد بناؤها كلها معادلات تُحسب عند الفتح.
B16: 4) أسماء الأنشطة | C16: حدّثت أسماء الأنشطة مع بقاء المعرفات القديمة (act_construction = «المهن الأولية») — المعرفات مفاتيح ثابتة ولا يلزم تغييرها، والأسماء المعروضة تتبع عمود «النشاط».
B17: 5) مؤشر kpi_005 | C17: قيمته الحالية أصبحت 136,437 وتطابق الآن الطاقة الاستيعابية — حُدّثت ملاحظته.
B19: قواعد التحرير العامة (كما في النسخة الأولى)
B20: لا تغيّر | C20: المعرفات وأسماء الأوراق والأعمدة.
B21: الخلايا الرمادية | C21: مشتقة بمعادلات — عدّل المدخلات الصفراء فقط.
B22: النسب | C22: كسور عشرية تُعرض بتنسيق ٪ (0.816 = 81.6٪).
B23: الحالات | C23: منجزة / جاري العمل / متأخرة / لم تبدأ بعد.

Sheet 02_البيانات_الرئيسية
A1: المعرف | B1: المؤشر | C1: القيمة | D1: الوحدة | E1: الفترة | F1: calculation_type | G1: جودة_البيانات | H1: الجهة_المصدرة_للبيانات | I1: المصدر | J1: حالة_المصدر | K1: ملاحظات_المصدر | L1: ملاحظات
A2: meta_today | B2: تاريخ اليوم المرجعي | C2: 46251 | D2: تاريخ | E2: - | F2: input | G2: يحتاج مراجعة | L2: يتحكم في حالات المبادرات وخط «اليوم»
A3: meta_asof | B3: فترة العرض المعلنة | C3: أغسطس 2026 | D3: نص | E3: - | F3: input | G3: يحتاج مراجعة
A4: main_demand | B4: إجمالي الطلب | C4: ='03_العرض_والطلب'!C2 -> 2800000 | D4: فرد | E4: أغسطس 2026 | F4: derived | G4: يحتاج مراجعة | H4: غير محدد / يحتاج تحديث | J4: غير محدد
A5: main_supply | B5: العرض / الطاقة الاستيعابية | C5: ='07_التراخيص_الشهرية'!I14 -> 136437 | D5: سرير | E5: أغسطس 2026 | F5: derived | G5: يحتاج مراجعة | H5: غير محدد / يحتاج تحديث | J5: غير محدد
A6: main_gap | B6: الفجوة | C6: ='03_العرض_والطلب'!C6 -> 2663563 | D6: سرير | E6: أغسطس 2026 | F6: derived | G6: يحتاج مراجعة
A7: main_coverage | B7: نسبة التغطية | C7: ='03_العرض_والطلب'!C7 -> 0.0487275 | D7: نسبة | E7: أغسطس 2026 | F7: derived | G7: يحتاج مراجعة
A8: main_building | B8: رخص البناء الحالية | C8: ='07_التراخيص_الشهرية'!G14 -> 165 | D8: رخصة | E8: أغسطس 2026 | F8: derived | G8: يحتاج مراجعة | H8: الإدارة العامة للتراخيص | J8: أولي
A9: main_operational | B9: الرخص التشغيلية الحالية | C9: ='07_التراخيص_الشهرية'!H14 -> 715 | D9: رخصة | E9: أغسطس 2026 | F9: derived | G9: يحتاج مراجعة | H9: غير محدد / يحتاج تحديث | J9: غير محدد | K9: ليست من الإدارة العامة للتراخيص
A10: main_inspectors | B10: إجمالي المراقبين | C10: ='11_الرقابة_حسب_القطاع'!C8 -> 18 | D10: مراقب | E10: أغسطس 2026 | F10: derived | G10: يحتاج مراجعة | H10: غير محدد / يحتاج تحديث | J10: غير محدد
A11: main_violations | B11: إجمالي المخالفات | C11: ='11_الرقابة_حسب_القطاع'!E8 -> 3617 | D11: مخالفة | E11: آخر 12 شهراً | F11: derived | G11: يحتاج مراجعة | H11: غير محدد / يحتاج تحديث | J11: غير محدد
A12: main_visits | B12: إجمالي الزيارات | C12: ='11_الرقابة_حسب_القطاع'!D8 -> 19651 | D12: زيارة | E12: آخر 12 شهراً | F12: derived | G12: يحتاج مراجعة | H12: غير محدد / يحتاج تحديث | J12: غير محدد
A13: main_compliance | B13: نسبة الامتثال | C13: ='10_الرقابة'!C5 -> 0.816 | D13: نسبة | E13: آخر 12 شهراً | F13: derived | G13: يحتاج مراجعة | H13: غير محدد / يحتاج تحديث | J13: غير محدد
A14: main_ini_total | B14: إجمالي المبادرات | C14: 18 | D14: مبادرة | E14: - | F14: input | G14: معتمد | L14: يتحدث من عدد صفوف ورقة 14 عند الاستيراد

Sheet 03_العرض_والطلب
A1: metric_id | B1: اسم_المؤشر | C1: القيمة | D1: الوحدة | E1: الفترة | F1: calculation_type | G1: calculation_rule | H1: جودة_البيانات | I1: الجهة_المصدرة_للبيانات | J1: المصدر | K1: حالة_المصدر | L1: ملاحظات_المصدر | M1: ملاحظات
A2: sd_demand_total | B2: إجمالي الطلب | C2: 2800000 | D2: فرد | E2: أغسطس 2026 | F2: input | H2: يحتاج مراجعة | I2: غير محدد / يحتاج تحديث | K2: غير محدد | M2: يساوي مجموع القطاعات والياقات والأنشطة
A3: sd_collar_blue | B3: الياقة الزرقاء | C3: 1848000 | D3: فرد | E3: أغسطس 2026 | F3: input | H3: يحتاج مراجعة | I3: غير محدد / يحتاج تحديث | K3: غير محدد
A4: sd_collar_white | B4: الياقة البيضاء | C4: 952000 | D4: فرد | E4: أغسطس 2026 | F4: input | H4: يحتاج مراجعة | I4: غير محدد / يحتاج تحديث | K4: غير محدد
A5: sd_supply | B5: العرض الحالي (الطاقة الاستيعابية) | C5: ='07_التراخيص_الشهرية'!I14 -> 136437 | D5: سرير | E5: أغسطس 2026 | F5: derived | G5: الطاقة التراكمية لآخر شهر (ورقة 07) | H5: يحتاج مراجعة | I5: غير محدد / يحتاج تحديث | K5: غير محدد | L5: ليست من الإدارة العامة للتراخيص — الجهة الفعلية تحتاج تحديداً
A6: sd_gap | B6: فجوة الإيواء | C6: =C2-C5 -> 2663563 | D6: سرير | E6: أغسطس 2026 | F6: derived | G6: الطلب − العرض | H6: يحتاج مراجعة
A7: sd_coverage | B7: نسبة تغطية الطلب | C7: =C5/C2 -> 0.0487275 | D7: نسبة | E7: أغسطس 2026 | F7: derived | G7: العرض ÷ الطلب | H7: يحتاج مراجعة
A8: sd_gap_pct | B8: نسبة الفجوة | C8: =C6/C2 -> 0.9512725 | D8: نسبة | E8: أغسطس 2026 | F8: derived | G8: الفجوة ÷ الطلب | H8: يحتاج مراجعة
A9: sd_multiple | B9: مضاعف الطلب مقابل العرض | C9: =C2/C5 -> 20.522292 | D9: مرة | E9: أغسطس 2026 | F9: derived | G9: الطلب ÷ العرض | H9: يحتاج مراجعة

Sheet 04_العرض_والطلب_حسب_القطاع
A1: sector_id | B1: القطاع | C1: الطلب | D1: العرض | E1: الفجوة | F1: نسبة_التغطية | G1: الوحدة | H1: calculation_type | I1: جودة_البيانات | J1: الجهة_المصدرة_للبيانات | K1: المصدر | L1: حالة_المصدر | M1: ملاحظات_المصدر | N1: ملاحظات
A2: sector_north | B2: قطاع الشمال | C2: 471710 | D2: ='08_التراخيص_حسب_القطاع'!F2 -> 29081 | E2: =C2-D2 -> 442629 | F2: =D2/C2 -> 0.061650166 | G2: فرد/سرير | H2: الطلب input؛ الباقي derived | I2: يحتاج مراجعة | J2: غير محدد / يحتاج تحديث | L2: غير محدد | N2: العرض مرجع من ورقة 08
A3: sector_east | B3: قطاع الشرق | C3: 433134 | D3: ='08_التراخيص_حسب_القطاع'!F3 -> 22102 | E3: =C3-D3 -> 411032 | F3: =D3/C3 -> 0.051028088 | G3: فرد/سرير | H3: الطلب input؛ الباقي derived | I3: يحتاج مراجعة | J3: غير محدد / يحتاج تحديث | L3: غير محدد | N3: العرض مرجع من ورقة 08
A4: sector_center | B4: قطاع الوسط | C4: 478711 | D4: ='08_التراخيص_حسب_القطاع'!F4 -> 9043 | E4: =C4-D4 -> 469668 | F4: =D4/C4 -> 0.018890312 | G4: فرد/سرير | H4: الطلب input؛ الباقي derived | I4: يحتاج مراجعة | J4: غير محدد / يحتاج تحديث | L4: غير محدد | N4: العرض مرجع من ورقة 08
A5: sector_west | B5: قطاع الغرب | C5: 603504 | D5: ='08_التراخيص_حسب_القطاع'!F5 -> 19673 | E5: =C5-D5 -> 583831 | F5: =D5/C5 -> 0.032597961 | G5: فرد/سرير | H5: الطلب input؛ الباقي derived | I5: يحتاج مراجعة | J5: غير محدد / يحتاج تحديث | L5: غير محدد | N5: العرض مرجع من ورقة 08
A6: sector_south | B6: قطاع الجنوب | C6: 812941 | D6: ='08_التراخيص_حسب_القطاع'!F6 -> 56538 | E6: =C6-D6 -> 756403 | F6: =D6/C6 -> 0.069547483 | G6: فرد/سرير | H6: الطلب input؛ الباقي derived | I6: يحتاج مراجعة | J6: غير محدد / يحتاج تحديث | L6: غير محدد | N6: العرض مرجع من ورقة 08
B8: الإجمالي (تحقق) | C8: =SUM(C2:C6) -> 2800000 | D8: =SUM(D2:D6) -> 136437 | E8: =SUM(E2:E6) -> 2663563 | F8: =D8/C8 -> 0.0487275 | H8: derived | N8: لا يشمل العرضُ هنا صفَّ «غير مصنف قطاعياً» في 08 إلا في طاقته (صفر حالياً)

Sheet 05_الطلب_حسب_النشاط
A1: activity_id | B1: النشاط | C1: الطلب | D1: الوحدة | E1: الترتيب | F1: جودة_البيانات | G1: الجهة_المصدرة_للبيانات | H1: المصدر | I1: حالة_المصدر | J1: ملاحظات_المصدر | K1: ملاحظات
A2: act_construction | B2: المهن الأولية | C2: 1960000 | D2: فرد | E2: 1 | F2: يحتاج مراجعة | G2: غير محدد / يحتاج تحديث | I2: غير محدد | K2: المعرف ثابت من النسخة السابقة والاسم المعروض محدث
A3: act_trade | B3: مشغلو المصانع والآلات وعاملو التجميع | C3: 417200 | D3: فرد | E3: 2 | F3: يحتاج مراجعة | G3: غير محدد / يحتاج تحديث | I3: غير محدد | K3: المعرف ثابت من النسخة السابقة والاسم المعروض محدث
A4: act_industry | B4: عاملو الحرف ومن يرتبط بهم | C4: 364000 | D4: فرد | E4: 3 | F4: يحتاج مراجعة | G4: غير محدد / يحتاج تحديث | I4: غير محدد | K4: المعرف ثابت من النسخة السابقة والاسم المعروض محدث
A5: act_public_services | B5: مهن الزراعة وتربية الحيوان والطيور والصيد | C5: 36400 | D5: فرد | E5: 4 | F5: يحتاج مراجعة | G5: غير محدد / يحتاج تحديث | I5: غير محدد | K5: المعرف ثابت من النسخة السابقة والاسم المعروض محدث
A6: act_hospitality | B6: مهن البيع | C6: 16800 | D6: فرد | E6: 5 | F6: يحتاج مراجعة | G6: غير محدد / يحتاج تحديث | I6: غير محدد | K6: المعرف ثابت من النسخة السابقة والاسم المعروض محدث
A7: act_other | B7: قطاعات أخرى | C7: 5600 | D7: فرد | E7: 6 | F7: يحتاج مراجعة | G7: غير محدد / يحتاج تحديث | I7: غير محدد | K7: المعرف ثابت من النسخة السابقة والاسم المعروض محدث
B9: الإجمالي (تحقق) | C9: =SUM(C2:C7) -> 2800000 | K9: يجب أن يساوي إجمالي الطلب

Sheet 06_التراخيص
A1: metric_id | B1: المؤشر | C1: القيمة_الحالية | D1: قيمة_خط_الأساس | E1: التغير | F1: نسبة_التغير | G1: الوحدة | H1: تاريخ_خط_الأساس | I1: تاريخ_القيمة_الحالية | J1: calculation_type | K1: جودة_البيانات | L1: الجهة_المصدرة_للبيانات | M1: المصدر | N1: حالة_المصدر | O1: ملاحظات_المصدر | P1: ملاحظات
A2: lic_building | B2: رخص البناء | C2: ='07_التراخيص_الشهرية'!G14 -> 165 | D2: ='07_التراخيص_الشهرية'!G2 -> 63 | E2: =C2-D2 -> 102 | F2: =E2/D2 -> 1.6190476 | G2: رخصة | H2: 45900 | I2: 46265 | J2: derived | K2: يحتاج مراجعة | L2: الإدارة العامة للتراخيص | N2: أولي | P2: كل القيم مشتقة من ورقة 07 — عدّل هناك
A3: lic_operational | B3: الرخص التشغيلية | C3: ='07_التراخيص_الشهرية'!H14 -> 715 | D3: ='07_التراخيص_الشهرية'!H2 -> 218 | E3: =C3-D3 -> 497 | F3: =E3/D3 -> 2.2798165 | G3: رخصة | H3: 45900 | I3: 46265 | J3: derived | K3: يحتاج مراجعة | L3: غير محدد / يحتاج تحديث | N3: غير محدد | O3: لا تُنسب للإدارة العامة للتراخيص — الجهة الفعلية تحتاج تحديداً | P3: كل القيم مشتقة من ورقة 07 — عدّل هناك
A4: lic_capacity | B4: الطاقة الاستيعابية | C4: ='07_التراخيص_الشهرية'!I14 -> 136437 | D4: ='07_التراخيص_الشهرية'!I2 -> 19485 | E4: =C4-D4 -> 116952 | F4: =E4/D4 -> 6.0021555 | G4: سرير | H4: 45900 | I4: 46265 | J4: derived | K4: يحتاج مراجعة | L4: غير محدد / يحتاج تحديث | N4: غير محدد | O4: لا تُنسب للإدارة العامة للتراخيص — الجهة الفعلية تحتاج تحديداً | P4: كل القيم مشتقة من ورقة 07 — عدّل هناك

Sheet 07_التراخيص_الشهرية
A1: month_id | B1: الشهر | C1: التاريخ | D1: رخص_البناء_الجديدة | E1: الرخص_التشغيلية_الجديدة | F1: الطاقة_الاستيعابية_المضافة | G1: رخص_البناء_التراكمية | H1: الرخص_التشغيلية_التراكمية | I1: الطاقة_الاستيعابية_التراكمية | J1: جودة_البيانات | K1: ملاحظات
A2: m_base | B2: ما قبل سبتمبر 2025 | C2: 45900 | G2: 63 | H2: 218 | I2: 19485 | J2: يحتاج مراجعة | K2: رصيد خط الأساس التراكمي (مدخل) — صُحّح موضعه من أعمدة الإضافات في المسودة
A3: m2025_09 | B3: سبتمبر 2025 | C3: 45901 | D3: 7 | E3: 14 | F3: 2428 | G3: =G2+D3 -> 70 | H3: =H2+E3 -> 232 | I3: =I2+F3 -> 21913 | J3: يحتاج مراجعة
A4: m2025_10 | B4: أكتوبر 2025 | C4: 45931 | D4: 3 | E4: 84 | F4: 21810 | G4: =G3+D4 -> 73 | H4: =H3+E4 -> 316 | I4: =I3+F4 -> 43723 | J4: يحتاج مراجعة
A5: m2025_11 | B5: نوفمبر 2025 | C5: 45962 | D5: 0 | E5: 145 | F5: 27352 | G5: =G4+D5 -> 73 | H5: =H4+E5 -> 461 | I5: =I4+F5 -> 71075 | J5: يحتاج مراجعة
A6: m2025_12 | B6: ديسمبر 2025 | C6: 45992 | D6: 7 | E6: 34 | F6: 3124 | G6: =G5+D6 -> 80 | H6: =H5+E6 -> 495 | I6: =I5+F6 -> 74199 | J6: يحتاج مراجعة
A7: m2026_01 | B7: يناير 2026 | C7: 46023 | D7: 5 | E7: 16 | F7: 2483 | G7: =G6+D7 -> 85 | H7: =H6+E7 -> 511 | I7: =I6+F7 -> 76682 | J7: يحتاج مراجعة
A8: m2026_02 | B8: فبراير 2026 | C8: 46054 | D8: 6 | E8: 29 | F8: 9885 | G8: =G7+D8 -> 91 | H8: =H7+E8 -> 540 | I8: =I7+F8 -> 86567 | J8: يحتاج مراجعة
A9: m2026_03 | B9: مارس 2026 | C9: 46082 | D9: 49 | E9: 29 | F9: 4680 | G9: =G8+D9 -> 140 | H9: =H8+E9 -> 569 | I9: =I8+F9 -> 91247 | J9: يحتاج مراجعة
A10: m2026_04 | B10: أبريل 2026 | C10: 46113 | D10: 15 | E10: 42 | F10: 16840 | G10: =G9+D10 -> 155 | H10: =H9+E10 -> 611 | I10: =I9+F10 -> 108087 | J10: يحتاج مراجعة
A11: m2026_05 | B11: مايو 2026 | C11: 46143 | D11: 6 | E11: 34 | F11: 5438 | G11: =G10+D11 -> 161 | H11: =H10+E11 -> 645 | I11: =I10+F11 -> 113525 | J11: يحتاج مراجعة
A12: m2026_06 | B12: يونيو 2026 | C12: 46174 | D12: 4 | E12: 37 | F12: 9684 | G12: =G11+D12 -> 165 | H12: =H11+E12 -> 682 | I12: =I11+F12 -> 123209 | J12: يحتاج مراجعة
A13: m2026_07 | B13: يوليو 2026 | C13: 46204 | D13: 0 | E13: 33 | F13: 13228 | G13: =G12+D13 -> 165 | H13: =H12+E13 -> 715 | I13: =I12+F13 -> 136437 | J13: يحتاج مراجعة
A14: m2026_08 | B14: أغسطس 2026 | C14: 46235 | D14: 0 | E14: 0 | F14: 0 | G14: =G13+D14 -> 165 | H14: =H13+E14 -> 715 | I14: =I13+F14 -> 136437 | J14: يحتاج مراجعة

Sheet 08_التراخيص_حسب_القطاع
A1: sector_id | B1: القطاع | C1: رخص_البناء | D1: الرخص_التشغيلية | E1: إجمالي_الرخص | F1: الطاقة_الاستيعابية | G1: calculation_type | H1: جودة_البيانات | I1: الجهة_المصدرة_للبيانات | J1: المصدر | K1: حالة_المصدر | L1: ملاحظات_المصدر | M1: ملاحظات
A2: sector_north | B2: قطاع الشمال | C2: 0 | D2: 81 | E2: =C2+D2 -> 81 | F2: 29081 | G2: الإجمالي derived؛ الباقي input | H2: يحتاج مراجعة | I2: رخص البناء: الإدارة العامة للتراخيص؛ الباقي: غير محدد / يحتاج تحديث | K2: أولي | L2: انظر ورقة 19 للملكية بحسب العمود
A3: sector_east | B3: قطاع الشرق | C3: 8 | D3: 197 | E3: =C3+D3 -> 205 | F3: 22102 | G3: الإجمالي derived؛ الباقي input | H3: يحتاج مراجعة | I3: رخص البناء: الإدارة العامة للتراخيص؛ الباقي: غير محدد / يحتاج تحديث | K3: أولي | L3: انظر ورقة 19 للملكية بحسب العمود
A4: sector_center | B4: قطاع الوسط | C4: 1 | D4: 64 | E4: =C4+D4 -> 65 | F4: 9043 | G4: الإجمالي derived؛ الباقي input | H4: يحتاج مراجعة | I4: رخص البناء: الإدارة العامة للتراخيص؛ الباقي: غير محدد / يحتاج تحديث | K4: أولي | L4: انظر ورقة 19 للملكية بحسب العمود
A5: sector_west | B5: قطاع الغرب | C5: 55 | D5: 151 | E5: =C5+D5 -> 206 | F5: 19673 | G5: الإجمالي derived؛ الباقي input | H5: يحتاج مراجعة | I5: رخص البناء: الإدارة العامة للتراخيص؛ الباقي: غير محدد / يحتاج تحديث | K5: أولي | L5: انظر ورقة 19 للملكية بحسب العمود
A6: sector_south | B6: قطاع الجنوب | C6: 44 | D6: 222 | E6: =C6+D6 -> 266 | F6: 56538 | G6: الإجمالي derived؛ الباقي input | H6: يحتاج مراجعة | I6: رخص البناء: الإدارة العامة للتراخيص؛ الباقي: غير محدد / يحتاج تحديث | K6: أولي | L6: انظر ورقة 19 للملكية بحسب العمود
A7: sector_unassigned | B7: غير مصنف قطاعياً | C7: 57 | D7: 0 | E7: =C7+D7 -> 57 | F7: 0 | G7: الإجمالي derived؛ الباقي input | H7: يحتاج مراجعة | I7: رخص البناء: الإدارة العامة للتراخيص؛ الباقي: غير محدد / يحتاج تحديث | K7: يحتاج مراجعة | L7: انظر ورقة 19 للملكية بحسب العمود | M7: صف مدرج في المسودة بلا اسم (57 رخصة بناء) — يحتاج قرارك: توزيعه أو اعتماده
B9: الإجمالي (تحقق) | C9: =SUM(C2:C7) -> 165 | D9: =SUM(D2:D7) -> 715 | E9: =SUM(E2:E7) -> 880 | F9: =SUM(F2:F7) -> 136437 | G9: derived | M9: يجب أن يطابق القيم الحالية في ورقة 06

Sheet 09_أنواع_المساكن
A1: housing_type_id | B1: نوع_السكن | C1: عدد_الرخص | D1: الطاقة_الاستيعابية | E1: الوحدة | F1: الترتيب | G1: icon_key | H1: جودة_البيانات | I1: الجهة_المصدرة_للبيانات | J1: المصدر | K1: حالة_المصدر | L1: ملاحظات_المصدر | M1: ملاحظات
A2: housing_compound | B2: مجمع سكني | C2: 56 | D2: 41724 | E2: رخصة/سرير | F2: 1 | G2: compound | H2: يحتاج مراجعة | I2: غير محدد / يحتاج تحديث | K2: غير محدد | L2: بيانات تشغيلية — لا تُنسب للإدارة العامة للتراخيص
A3: housing_building | B3: مبنى سكني | C3: 652 | D3: 87820 | E3: رخصة/سرير | F3: 2 | G3: building | H3: يحتاج مراجعة | I3: غير محدد / يحتاج تحديث | K3: غير محدد | L3: بيانات تشغيلية — لا تُنسب للإدارة العامة للتراخيص
A4: housing_cabins | B4: كبائن متنقلة | C4: 7 | D4: 6893 | E4: رخصة/سرير | F4: 3 | G4: cabins | H4: يحتاج مراجعة | I4: غير محدد / يحتاج تحديث | K4: غير محدد | L4: بيانات تشغيلية — لا تُنسب للإدارة العامة للتراخيص
B6: الإجمالي (تحقق) | C6: =SUM(C2:C4) -> 715 | D6: =SUM(D2:D4) -> 136437 | M6: العدد = الرخص التشغيلية الحالية؛ الأسرّة = الطاقة الحالية

Sheet 10_الرقابة
A1: metric_id | B1: المؤشر | C1: القيمة | D1: الوحدة | E1: الفترة | F1: calculation_type | G1: calculation_rule | H1: جودة_البيانات | I1: الجهة_المصدرة_للبيانات | J1: المصدر | K1: حالة_المصدر | L1: ملاحظات_المصدر | M1: ملاحظات
A2: ctl_inspectors_total | B2: إجمالي عدد المراقبين | C2: ='11_الرقابة_حسب_القطاع'!C8 -> 18 | D2: مراقب | E2: أغسطس 2026 | F2: derived | G2: مجموع القطاعات (ورقة 11) | H2: يحتاج مراجعة | I2: غير محدد / يحتاج تحديث | K2: غير محدد
A3: ctl_violations_total | B3: إجمالي عدد المخالفات | C3: ='11_الرقابة_حسب_القطاع'!E8 -> 3617 | D3: مخالفة | E3: آخر 12 شهراً | F3: derived | G3: مجموع القطاعات (ورقة 11) | H3: يحتاج مراجعة | I3: غير محدد / يحتاج تحديث | K3: غير محدد
A4: ctl_visits_total | B4: إجمالي الزيارات الرقابية | C4: ='11_الرقابة_حسب_القطاع'!D8 -> 19651 | D4: زيارة | E4: آخر 12 شهراً | F4: derived | G4: مجموع القطاعات (ورقة 11) | H4: يحتاج مراجعة | I4: غير محدد / يحتاج تحديث | K4: غير محدد
A5: ctl_compliance | B5: نسبة الامتثال | C5: 0.816 | D5: نسبة | E5: آخر 12 شهراً | F5: input | H5: يحتاج مراجعة | I5: غير محدد / يحتاج تحديث | K5: غير محدد
A6: ctl_closures_total | B6: إجمالي الإغلاقات | D6: إغلاق | E6: آخر 12 شهراً | F6: input | H6: غير متوفر | I6: غير محدد / يحتاج تحديث | K6: غير محدد

Sheet 11_الرقابة_حسب_القطاع
A1: sector_id | B1: القطاع | C1: عدد_المراقبين | D1: عدد_الزيارات | E1: عدد_المخالفات | F1: عدد_الإغلاقات | G1: جودة_البيانات | H1: الجهة_المصدرة_للبيانات | I1: المصدر | J1: حالة_المصدر | K1: ملاحظات_المصدر | L1: ملاحظات
A2: sector_north | B2: قطاع الشمال | C2: 4 | D2: 3538 | E2: 439 | G2: يحتاج مراجعة | H2: غير محدد / يحتاج تحديث | J2: غير محدد | L2: عدد الإغلاقات غير متوفر — أدخله إن توفر
A3: sector_east | B3: قطاع الشرق | C3: 4 | D3: 4716 | E3: 907 | G3: يحتاج مراجعة | H3: غير محدد / يحتاج تحديث | J3: غير محدد | L3: عدد الإغلاقات غير متوفر — أدخله إن توفر
A4: sector_center | B4: قطاع الوسط | C4: 4 | D4: 3341 | E4: 548 | G4: يحتاج مراجعة | H4: غير محدد / يحتاج تحديث | J4: غير محدد | L4: عدد الإغلاقات غير متوفر — أدخله إن توفر
A5: sector_west | B5: قطاع الغرب | C5: 3 | D5: 2553 | E5: 356 | G5: يحتاج مراجعة | H5: غير محدد / يحتاج تحديث | J5: غير محدد | L5: عدد الإغلاقات غير متوفر — أدخله إن توفر
A6: sector_south | B6: قطاع الجنوب | C6: 3 | D6: 5503 | E6: 1367 | G6: يحتاج مراجعة | H6: غير محدد / يحتاج تحديث | J6: غير محدد | L6: عدد الإغلاقات غير متوفر — أدخله إن توفر
B8: الإجمالي (تحقق) | C8: =SUM(C2:C6) -> 18 | D8: =SUM(D2:D6) -> 19651 | E8: =SUM(E2:E6) -> 3617 | F8: =SUM(F2:F6) -> 0

Sheet 12_المخالفات_حسب_النوع
A1: violation_type_id | B1: نوع_المخالفة | C1: عدد_المخالفات | D1: الترتيب | E1: جودة_البيانات | F1: الجهة_المصدرة_للبيانات | G1: المصدر | H1: حالة_المصدر | I1: ملاحظات_المصدر | J1: ملاحظات
A2: vt_overcrowding | B2: الاكتظاظ وتجاوز الطاقة الاستيعابية | C2: 1121 | D2: 1 | E2: يحتاج مراجعة | F2: غير محدد / يحتاج تحديث | H2: غير محدد
A3: vt_fire_safety | B3: اشتراطات السلامة والحماية من الحريق | C3: 868 | D3: 2 | E3: يحتاج مراجعة | F3: غير محدد / يحتاج تحديث | H3: غير محدد
A4: vt_hygiene | B4: النظافة والصحة العامة | C4: 615 | D4: 3 | E4: يحتاج مراجعة | F4: غير محدد / يحتاج تحديث | H4: غير محدد
A5: vt_unlicensed | B5: مزاولة النشاط بدون ترخيص | C5: 434 | D5: 4 | E5: يحتاج مراجعة | F5: غير محدد / يحتاج تحديث | H5: غير محدد
A6: vt_electric_plumbing | B6: مخالفات الكهرباء والسباكة | C6: 326 | D6: 5 | E6: يحتاج مراجعة | F6: غير محدد / يحتاج تحديث | H6: غير محدد
A7: vt_ventilation | B7: التهوية والعزل غير المطابق | C7: 253 | D7: 6 | E7: يحتاج مراجعة | F7: غير محدد / يحتاج تحديث | H7: غير محدد
B9: الإجمالي (تحقق) | C9: =SUM(C2:C7) -> 3617 | J9: يجب أن يساوي إجمالي المخالفات

Sheet 13_الأحياء
A1: neighborhood_id | B1: الحي | C1: sector_id | D1: القطاع | E1: رخص_البناء | F1: الرخص_التشغيلية | G1: الطاقة_الاستيعابية | H1: عدد_المخالفات | I1: عدد_الزيارات | J1: خط_العرض | K1: خط_الطول | L1: جودة_البيانات | M1: الجهة_المصدرة_للبيانات | N1: المصدر | O1: حالة_المصدر | P1: ملاحظات_المصدر | Q1: ملاحظات
A2: nb_01 | B2: حي الملقا | C2: sector_north | D2: قطاع الشمال | E2: 6 | F2: 5 | G2: 21500 | H2: 84 | L2: عينة | M2: غير محدد / يحتاج تحديث | O2: غير محدد | Q2: بيانات عينة — لم تُحدّث في المسودة الأولى؛ نقاط التركّز تُرسم عند مركز مضلع الحي من ملف الحدود
A3: nb_02 | B3: حي الصحافة | C3: sector_north | D3: قطاع الشمال | E3: 5 | F3: 4 | G3: 16800 | H3: 61 | L3: عينة | M3: غير محدد / يحتاج تحديث | O3: غير محدد | Q3: بيانات عينة — لم تُحدّث في المسودة الأولى؛ نقاط التركّز تُرسم عند مركز مضلع الحي من ملف الحدود
A4: nb_03 | B4: حي حطين | C4: sector_north | D4: قطاع الشمال | E4: 4 | F4: 4 | G4: 15200 | H4: 57 | L4: عينة | M4: غير محدد / يحتاج تحديث | O4: غير محدد | Q4: بيانات عينة — لم تُحدّث في المسودة الأولى؛ نقاط التركّز تُرسم عند مركز مضلع الحي من ملف الحدود
A5: nb_04 | B5: حي الياسمين | C5: sector_north | D5: قطاع الشمال | E5: 3 | F5: 3 | G5: 11900 | H5: 48 | L5: عينة | M5: غير محدد / يحتاج تحديث | O5: غير محدد | Q5: بيانات عينة — لم تُحدّث في المسودة الأولى؛ نقاط التركّز تُرسم عند مركز مضلع الحي من ملف الحدود
A6: nb_05 | B6: حي النسيم الشرقي | C6: sector_east | D6: قطاع الشرق | E6: 7 | F6: 8 | G6: 34600 | H6: 216 | L6: عينة | M6: غير محدد / يحتاج تحديث | O6: غير محدد | Q6: بيانات عينة — لم تُحدّث في المسودة الأولى؛ نقاط التركّز تُرسم عند مركز مضلع الحي من ملف الحدود
A7: nb_06 | B7: حي السلي | C7: sector_east | D7: قطاع الشرق | E7: 6 | F7: 6 | G7: 30200 | H7: 246 | L7: عينة | M7: غير محدد / يحتاج تحديث | O7: غير محدد | Q7: بيانات عينة — لم تُحدّث في المسودة الأولى؛ نقاط التركّز تُرسم عند مركز مضلع الحي من ملف الحدود
A8: nb_07 | B8: حي النظيم | C8: sector_east | D8: قطاع الشرق | E8: 5 | F8: 5 | G8: 24800 | H8: 168 | L8: عينة | M8: غير محدد / يحتاج تحديث | O8: غير محدد | Q8: بيانات عينة — لم تُحدّث في المسودة الأولى؛ نقاط التركّز تُرسم عند مركز مضلع الحي من ملف الحدود
A9: nb_08 | B9: حي النسيم الغربي | C9: sector_east | D9: قطاع الشرق | E9: 4 | F9: 6 | G9: 27400 | H9: 152 | L9: عينة | M9: غير محدد / يحتاج تحديث | O9: غير محدد | Q9: بيانات عينة — لم تُحدّث في المسودة الأولى؛ نقاط التركّز تُرسم عند مركز مضلع الحي من ملف الحدود
A10: nb_09 | B10: حي منفوحة | C10: sector_center | D10: قطاع الوسط | E10: 4 | F10: 7 | G10: 23200 | H10: 187 | L10: عينة | M10: غير محدد / يحتاج تحديث | O10: غير محدد | Q10: بيانات عينة — لم تُحدّث في المسودة الأولى؛ نقاط التركّز تُرسم عند مركز مضلع الحي من ملف الحدود
A11: nb_10 | B11: حي غبيرة | C11: sector_center | D11: قطاع الوسط | E11: 3 | F11: 5 | G11: 19400 | H11: 149 | L11: عينة | M11: غير محدد / يحتاج تحديث | O11: غير محدد | Q11: بيانات عينة — لم تُحدّث في المسودة الأولى؛ نقاط التركّز تُرسم عند مركز مضلع الحي من ملف الحدود
A12: nb_11 | B12: حي الجرادية | C12: sector_center | D12: قطاع الوسط | E12: 2 | F12: 4 | G12: 15300 | H12: 102 | L12: عينة | M12: غير محدد / يحتاج تحديث | O12: غير محدد | Q12: بيانات عينة — لم تُحدّث في المسودة الأولى؛ نقاط التركّز تُرسم عند مركز مضلع الحي من ملف الحدود
A13: nb_12 | B13: حي الديرة | C13: sector_center | D13: قطاع الوسط | E13: 2 | F13: 3 | G13: 11600 | H13: 76 | L13: عينة | M13: غير محدد / يحتاج تحديث | O13: غير محدد | Q13: بيانات عينة — لم تُحدّث في المسودة الأولى؛ نقاط التركّز تُرسم عند مركز مضلع الحي من ملف الحدود
... A21: nb_20 | B21: حي بدر | C21: sector_south | D21: قطاع الجنوب | E21: 4 | F21: 4 | G21: 17600 | H21: 214 | L21: عينة | M21: غير محدد / يحتاج تحديث | O21: غير محدد | Q21: بيانات عينة — لم تُحدّث في المسودة الأولى؛ نقاط التركّز تُرسم عند مركز مضلع الحي من ملف الحدود

Sheet 14_المبادرات
A1: initiative_id | B1: رقم_المبادرة | C1: اسم_المبادرة | D1: goal_id | E1: الهدف | F1: الحالة_في_الملف | G1: الحالة_المعروضة_حالياً | H1: تاريخ_البدء | I1: تاريخ_الانتهاء | J1: الجهة_المسؤولة | K1: جودة_البيانات | L1: الجهة_المصدرة_للبيانات | M1: المصدر | N1: حالة_المصدر | O1: ملاحظات_المصدر | P1: ملاحظات
A2: ini_1_1 | B2: 1.1 | C2: دراسة الطلب والعرض على السكن الجماعي للأفراد | D2: g1 | E2: الهدف الأول | F2: منجزة | G2: منجزة | K2: يحتاج مراجعة | L2: غير محدد / يحتاج تحديث | N2: غير محدد | P2: حالة صريحة في الملف
A3: ini_1_2 | B3: 1.2 | C3: تسهيل رحلة إصدار التراخيص وزيادة الوعي في المنظومة | D3: g1 | E3: الهدف الأول | G3: متأخرة | H3: 46113 | I3: 46142 | K3: يحتاج مراجعة | L3: غير محدد / يحتاج تحديث | N3: غير محدد | P3: الحالة المعروضة محتسبة زمنياً بتاريخ 2026-08-17
A4: ini_1_3 | B4: 1.3 | C4: طرح فرص استثمارية ورفع مستوى رضا المستثمرين | D4: g1 | E4: الهدف الأول | G4: متأخرة | H4: 46113 | I4: 46203 | K4: يحتاج مراجعة | L4: غير محدد / يحتاج تحديث | N4: غير محدد | P4: الحالة المعروضة محتسبة زمنياً بتاريخ 2026-08-17
A5: ini_1_4 | B5: 1.4 | C5: تقنين السكن الجماعي غير المرخص | D5: g1 | E5: الهدف الأول | G5: جاري العمل | H5: 46113 | I5: 46507 | K5: يحتاج مراجعة | L5: غير محدد / يحتاج تحديث | N5: غير محدد | P5: الحالة المعروضة محتسبة زمنياً بتاريخ 2026-08-17
A6: ini_1_5 | B6: 1.5 | C6: احتضان مشاريع نموذجية للسكن الجماعي في المدينة | D6: g1 | E6: الهدف الأول | G6: جاري العمل | H6: 46113 | I6: 46387 | K6: يحتاج مراجعة | L6: غير محدد / يحتاج تحديث | N6: غير محدد | P6: الحالة المعروضة محتسبة زمنياً بتاريخ 2026-08-17
A7: ini_1_6 | B7: 1.6 | C7: إضافة فئات جديدة للسكن الجماعي للأفراد | D7: g1 | E7: الهدف الأول | G7: متأخرة | H7: 46113 | I7: 46234 | K7: يحتاج مراجعة | L7: غير محدد / يحتاج تحديث | N7: غير محدد | P7: الحالة المعروضة محتسبة زمنياً بتاريخ 2026-08-17
A8: ini_2_1 | B8: 2.1 | C8: تنظيم التعاقد الإيجاري للسكن الجماعي | D8: g2 | E8: الهدف الثاني | G8: متأخرة | H8: 46113 | I8: 46234 | K8: يحتاج مراجعة | L8: غير محدد / يحتاج تحديث | N8: غير محدد | P8: الحالة المعروضة محتسبة زمنياً بتاريخ 2026-08-17
A9: ini_2_2 | B9: 2.2 | C9: ربط مكان سكن العامل بالهوية | D9: g2 | E9: الهدف الثاني | G9: جاري العمل | H9: 46113 | I9: 46295 | K9: يحتاج مراجعة | L9: غير محدد / يحتاج تحديث | N9: غير محدد | P9: الحالة المعروضة محتسبة زمنياً بتاريخ 2026-08-17
A10: ini_2_3 | B10: 2.3 | C10: إلزام المنشآت بتسكين العاملين في سكن مرخص | D10: g2 | E10: الهدف الثاني | G10: جاري العمل | H10: 46113 | I10: 46507 | K10: يحتاج مراجعة | L10: غير محدد / يحتاج تحديث | N10: غير محدد | P10: الحالة المعروضة محتسبة زمنياً بتاريخ 2026-08-17
A11: ini_2_4 | B11: 2.4 | C11: تنظيم المباني ذو الطاقة الاستيعابية أقل من 20 | D11: g2 | E11: الهدف الثاني | G11: جاري العمل | H11: 46113 | I11: 46295 | K11: يحتاج مراجعة | L11: غير محدد / يحتاج تحديث | N11: غير محدد | P11: الحالة المعروضة محتسبة زمنياً بتاريخ 2026-08-17
A12: ini_3_1 | B12: 3.1 | C12: تفعيل الرقابة الاستباقية لما قبل إصدار التراخيص | D12: g3 | E12: الهدف الثالث | F12: منجزة | G12: منجزة | K12: يحتاج مراجعة | L12: غير محدد / يحتاج تحديث | N12: غير محدد | P12: حالة صريحة في الملف
A13: ini_3_2 | B13: 3.2 | C13: زيادة كفاءة التفتيش الميداني | D13: g3 | E13: الهدف الثالث | G13: متأخرة | H13: 46113 | I13: 46234 | K13: يحتاج مراجعة | L13: غير محدد / يحتاج تحديث | N13: غير محدد | P13: الحالة المعروضة محتسبة زمنياً بتاريخ 2026-08-17
A14: ini_3_3 | B14: 3.3 | C14: تحديث آلية المخالفات | D14: g3 | E14: الهدف الثالث | G14: متأخرة | H14: 46113 | I14: 46203 | K14: يحتاج مراجعة | L14: غير محدد / يحتاج تحديث | N14: غير محدد | P14: الحالة المعروضة محتسبة زمنياً بتاريخ 2026-08-17
A15: ini_4_1 | B15: 4.1 | C15: تفعيل نموذج الحوكمة | D15: g4 | E15: الممكن | G15: متأخرة | H15: 46113 | I15: 46142 | K15: يحتاج مراجعة | L15: غير محدد / يحتاج تحديث | N15: غير محدد | P15: الحالة المعروضة محتسبة زمنياً بتاريخ 2026-08-17
A16: ini_4_2 | B16: 4.2 | C16: تطبيق خطة إدارة الأداء والمخاطر | D16: g4 | E16: الممكن | G16: جاري العمل | H16: 46174 | I16: 46265 | K16: يحتاج مراجعة | L16: غير محدد / يحتاج تحديث | N16: غير محدد | P16: الحالة المعروضة محتسبة زمنياً بتاريخ 2026-08-17
A17: ini_4_3 | B17: 4.3 | C17: تحسين آليات التواصل | D17: g4 | E17: الممكن | G17: جاري العمل | H17: 46113 | I17: 46295 | K17: يحتاج مراجعة | L17: غير محدد / يحتاج تحديث | N17: غير محدد | P17: الحالة المعروضة محتسبة زمنياً بتاريخ 2026-08-17
A18: ini_4_4 | B18: 4.4 | C18: تطبيق نموذجي تشغيلي للمنظومة | D18: g4 | E18: الممكن | G18: جاري العمل | H18: 46204 | I18: 46295 | K18: يحتاج مراجعة | L18: غير محدد / يحتاج تحديث | N18: غير محدد | P18: الحالة المعروضة محتسبة زمنياً بتاريخ 2026-08-17
A19: ini_4_5 | B19: 4.5 | C19: رقمنة العمليات والإجراءات في منظومة السكن الجماعي | D19: g4 | E19: الممكن | G19: جاري العمل | H19: 46143 | I19: 46324 | K19: يحتاج مراجعة | L19: غير محدد / يحتاج تحديث | N19: غير محدد | P19: الحالة المعروضة محتسبة زمنياً بتاريخ 2026-08-17

Sheet 15_خطة_المبادرات
A1: plan_item_id | B1: initiative_id | C1: رقم_المبادرة | D1: المبادرة | E1: اسم_النشاط | F1: تاريخ_البدء | G1: تاريخ_الانتهاء | H1: الحالة | I1: الجهة_المسؤولة | J1: الترتيب | K1: جودة_البيانات | L1: الجهة_المصدرة_للبيانات | M1: المصدر | N1: حالة_المصدر | O1: ملاحظات_المصدر | P1: ملاحظات
A2: plan_1_1 | B2: ini_1_1 | C2: 1.1 | D2: دراسة الطلب والعرض على السكن الجماعي للأفراد | E2: دراسة الطلب والعرض على السكن الجماعي للأفراد | H2: منجزة | J2: 1 | K2: يحتاج مراجعة | L2: غير محدد / يحتاج تحديث | N2: غير محدد | P2: بند واحد لكل مبادرة — أضف صفوف أنشطة فرعية إن رغبت
A3: plan_1_2 | B3: ini_1_2 | C3: 1.2 | D3: تسهيل رحلة إصدار التراخيص وزيادة الوعي في المنظومة | E3: تسهيل رحلة إصدار التراخيص وزيادة الوعي في المنظومة | F3: 46113 | G3: 46142 | H3: متأخرة | J3: 2 | K3: يحتاج مراجعة | L3: غير محدد / يحتاج تحديث | N3: غير محدد | P3: بند واحد لكل مبادرة — أضف صفوف أنشطة فرعية إن رغبت
A4: plan_1_3 | B4: ini_1_3 | C4: 1.3 | D4: طرح فرص استثمارية ورفع مستوى رضا المستثمرين | E4: طرح فرص استثمارية ورفع مستوى رضا المستثمرين | F4: 46113 | G4: 46203 | H4: متأخرة | J4: 3 | K4: يحتاج مراجعة | L4: غير محدد / يحتاج تحديث | N4: غير محدد | P4: بند واحد لكل مبادرة — أضف صفوف أنشطة فرعية إن رغبت
A5: plan_1_4 | B5: ini_1_4 | C5: 1.4 | D5: تقنين السكن الجماعي غير المرخص | E5: تقنين السكن الجماعي غير المرخص | F5: 46113 | G5: 46507 | H5: جاري العمل | J5: 4 | K5: يحتاج مراجعة | L5: غير محدد / يحتاج تحديث | N5: غير محدد | P5: بند واحد لكل مبادرة — أضف صفوف أنشطة فرعية إن رغبت
A6: plan_1_5 | B6: ini_1_5 | C6: 1.5 | D6: احتضان مشاريع نموذجية للسكن الجماعي في المدينة | E6: احتضان مشاريع نموذجية للسكن الجماعي في المدينة | F6: 46113 | G6: 46387 | H6: جاري العمل | J6: 5 | K6: يحتاج مراجعة | L6: غير محدد / يحتاج تحديث | N6: غير محدد | P6: بند واحد لكل مبادرة — أضف صفوف أنشطة فرعية إن رغبت
A7: plan_1_6 | B7: ini_1_6 | C7: 1.6 | D7: إضافة فئات جديدة للسكن الجماعي للأفراد | E7: إضافة فئات جديدة للسكن الجماعي للأفراد | F7: 46113 | G7: 46234 | H7: متأخرة | J7: 6 | K7: يحتاج مراجعة | L7: غير محدد / يحتاج تحديث | N7: غير محدد | P7: بند واحد لكل مبادرة — أضف صفوف أنشطة فرعية إن رغبت
A8: plan_2_1 | B8: ini_2_1 | C8: 2.1 | D8: تنظيم التعاقد الإيجاري للسكن الجماعي | E8: تنظيم التعاقد الإيجاري للسكن الجماعي | F8: 46113 | G8: 46234 | H8: متأخرة | J8: 7 | K8: يحتاج مراجعة | L8: غير محدد / يحتاج تحديث | N8: غير محدد | P8: بند واحد لكل مبادرة — أضف صفوف أنشطة فرعية إن رغبت
A9: plan_2_2 | B9: ini_2_2 | C9: 2.2 | D9: ربط مكان سكن العامل بالهوية | E9: ربط مكان سكن العامل بالهوية | F9: 46113 | G9: 46295 | H9: جاري العمل | J9: 8 | K9: يحتاج مراجعة | L9: غير محدد / يحتاج تحديث | N9: غير محدد | P9: بند واحد لكل مبادرة — أضف صفوف أنشطة فرعية إن رغبت
A10: plan_2_3 | B10: ini_2_3 | C10: 2.3 | D10: إلزام المنشآت بتسكين العاملين في سكن مرخص | E10: إلزام المنشآت بتسكين العاملين في سكن مرخص | F10: 46113 | G10: 46507 | H10: جاري العمل | J10: 9 | K10: يحتاج مراجعة | L10: غير محدد / يحتاج تحديث | N10: غير محدد | P10: بند واحد لكل مبادرة — أضف صفوف أنشطة فرعية إن رغبت
A11: plan_2_4 | B11: ini_2_4 | C11: 2.4 | D11: تنظيم المباني ذو الطاقة الاستيعابية أقل من 20 | E11: تنظيم المباني ذو الطاقة الاستيعابية أقل من 20 | F11: 46113 | G11: 46295 | H11: جاري العمل | J11: 10 | K11: يحتاج مراجعة | L11: غير محدد / يحتاج تحديث | N11: غير محدد | P11: بند واحد لكل مبادرة — أضف صفوف أنشطة فرعية إن رغبت
A12: plan_3_1 | B12: ini_3_1 | C12: 3.1 | D12: تفعيل الرقابة الاستباقية لما قبل إصدار التراخيص | E12: تفعيل الرقابة الاستباقية لما قبل إصدار التراخيص | H12: منجزة | J12: 11 | K12: يحتاج مراجعة | L12: غير محدد / يحتاج تحديث | N12: غير محدد | P12: بند واحد لكل مبادرة — أضف صفوف أنشطة فرعية إن رغبت
A13: plan_3_2 | B13: ini_3_2 | C13: 3.2 | D13: زيادة كفاءة التفتيش الميداني | E13: زيادة كفاءة التفتيش الميداني | F13: 46113 | G13: 46234 | H13: متأخرة | J13: 12 | K13: يحتاج مراجعة | L13: غير محدد / يحتاج تحديث | N13: غير محدد | P13: بند واحد لكل مبادرة — أضف صفوف أنشطة فرعية إن رغبت
A14: plan_3_3 | B14: ini_3_3 | C14: 3.3 | D14: تحديث آلية المخالفات | E14: تحديث آلية المخالفات | F14: 46113 | G14: 46203 | H14: متأخرة | J14: 13 | K14: يحتاج مراجعة | L14: غير محدد / يحتاج تحديث | N14: غير محدد | P14: بند واحد لكل مبادرة — أضف صفوف أنشطة فرعية إن رغبت
A15: plan_4_1 | B15: ini_4_1 | C15: 4.1 | D15: تفعيل نموذج الحوكمة | E15: تفعيل نموذج الحوكمة | F15: 46113 | G15: 46142 | H15: متأخرة | J15: 14 | K15: يحتاج مراجعة | L15: غير محدد / يحتاج تحديث | N15: غير محدد | P15: بند واحد لكل مبادرة — أضف صفوف أنشطة فرعية إن رغبت
A16: plan_4_2 | B16: ini_4_2 | C16: 4.2 | D16: تطبيق خطة إدارة الأداء والمخاطر | E16: تطبيق خطة إدارة الأداء والمخاطر | F16: 46174 | G16: 46265 | H16: جاري العمل | J16: 15 | K16: يحتاج مراجعة | L16: غير محدد / يحتاج تحديث | N16: غير محدد | P16: بند واحد لكل مبادرة — أضف صفوف أنشطة فرعية إن رغبت
A17: plan_4_3 | B17: ini_4_3 | C17: 4.3 | D17: تحسين آليات التواصل | E17: تحسين آليات التواصل | F17: 46113 | G17: 46295 | H17: جاري العمل | J17: 16 | K17: يحتاج مراجعة | L17: غير محدد / يحتاج تحديث | N17: غير محدد | P17: بند واحد لكل مبادرة — أضف صفوف أنشطة فرعية إن رغبت
A18: plan_4_4 | B18: ini_4_4 | C18: 4.4 | D18: تطبيق نموذجي تشغيلي للمنظومة | E18: تطبيق نموذجي تشغيلي للمنظومة | F18: 46204 | G18: 46295 | H18: جاري العمل | J18: 17 | K18: يحتاج مراجعة | L18: غير محدد / يحتاج تحديث | N18: غير محدد | P18: بند واحد لكل مبادرة — أضف صفوف أنشطة فرعية إن رغبت
A19: plan_4_5 | B19: ini_4_5 | C19: 4.5 | D19: رقمنة العمليات والإجراءات في منظومة السكن الجماعي | E19: رقمنة العمليات والإجراءات في منظومة السكن الجماعي | F19: 46143 | G19: 46324 | H19: جاري العمل | J19: 18 | K19: يحتاج مراجعة | L19: غير محدد / يحتاج تحديث | N19: غير محدد | P19: بند واحد لكل مبادرة — أضف صفوف أنشطة فرعية إن رغبت

Sheet 16_مؤشرات_الأداء
A1: kpi_id | B1: اسم_المؤشر | C1: goal_id | D1: الهدف | E1: خط_الأساس | F1: القيمة_الحالية | G1: المستهدف | H1: الوحدة | I1: نوع_المؤشر | J1: اتجاه_الأداء | K1: الفترة | L1: جودة_البيانات | M1: الجهة_المصدرة_للبيانات | N1: المصدر | O1: حالة_المصدر | P1: ملاحظات_المصدر | Q1: ملاحظات
A2: kpi_001 | B2: نسبة الالتزام باتفاقيات مستوى الخدمة للتراخيص | C2: g2 | D2: الهدف الثاني | E2: 0 | F2: 0.62 | G2: 0.8 | H2: نسبة | I2: نسبة | J2: الأعلى_أفضل | K2: أغسطس 2026 | L2: تجريبي | M2: غير محدد / يحتاج تحديث | N2: خطة العمل V.1.0.0 | O2: أولي | P2: خط الأساس والمستهدف من خطة العمل؛ جهة القيم الحالية غير محددة | Q2: خط الأساس والمستهدف من خطة العمل؛ القيمة الحالية تقديرية وتُستبدل بالفعلية
A3: kpi_002 | B3: نسبة تفعيل نموذج الحوكمة المحدث للسكن الجماعي | C3: g4 | D3: الممكن | E3: 0 | F3: 0.55 | G3: 1 | H3: نسبة | I3: نسبة | J3: الأعلى_أفضل | K3: أغسطس 2026 | L3: تجريبي | M3: غير محدد / يحتاج تحديث | N3: خطة العمل V.1.0.0 | O3: أولي | P3: خط الأساس والمستهدف من خطة العمل؛ جهة القيم الحالية غير محددة | Q3: خط الأساس والمستهدف من خطة العمل؛ القيمة الحالية تقديرية وتُستبدل بالفعلية
A4: kpi_003 | B4: عدد الأراضي المطروحة لبناء سكن جماعي للأفراد | C4: g1 | D4: الهدف الأول | E4: 0 | F4: 4 | G4: 10 | H4: أرض | I4: عدد | J4: الأعلى_أفضل | K4: أغسطس 2026 | L4: تجريبي | M4: غير محدد / يحتاج تحديث | N4: خطة العمل V.1.0.0 | O4: أولي | P4: خط الأساس والمستهدف من خطة العمل؛ جهة القيم الحالية غير محددة | Q4: خط الأساس والمستهدف من خطة العمل؛ القيمة الحالية تقديرية وتُستبدل بالفعلية
A5: kpi_004 | B5: عدد المشاريع النوعية في منظومة السكن الجماعي | C5: g1 | D5: الهدف الأول | E5: 0 | F5: 1 | G5: 3 | H5: مشروع | I5: عدد | J5: الأعلى_أفضل | K5: أغسطس 2026 | L5: تجريبي | M5: غير محدد / يحتاج تحديث | N5: خطة العمل V.1.0.0 | O5: أولي | P5: خط الأساس والمستهدف من خطة العمل؛ جهة القيم الحالية غير محددة | Q5: خط الأساس والمستهدف من خطة العمل؛ القيمة الحالية تقديرية وتُستبدل بالفعلية
A6: kpi_005 | B6: عدد الأسرّة المرخصة في مدينة الرياض | C6: g1 | D6: الهدف الأول | E6: 130000 | F6: 136437 | G6: 260000 | H6: سرير | I6: عدد | J6: الأعلى_أفضل | K6: أغسطس 2026 | L6: تجريبي | M6: غير محدد / يحتاج تحديث | N6: خطة العمل V.1.0.0 | O6: أولي | P6: خط الأساس والمستهدف من خطة العمل؛ جهة القيم الحالية غير محددة | Q6: حُدّثت القيمة الحالية في المسودة وتطابق الآن الطاقة الاستيعابية (ورقة 07)
A7: kpi_006 | B7: نسبة رضا المستثمرين | C7: g1 | D7: الهدف الأول | E7: 0.5 | F7: 0.54 | G7: 0.6 | H7: نسبة | I7: نسبة | J7: الأعلى_أفضل | K7: أغسطس 2026 | L7: تجريبي | M7: غير محدد / يحتاج تحديث | N7: خطة العمل V.1.0.0 | O7: أولي | P7: خط الأساس والمستهدف من خطة العمل؛ جهة القيم الحالية غير محددة | Q7: خط الأساس والمستهدف من خطة العمل؛ القيمة الحالية تقديرية وتُستبدل بالفعلية
A8: kpi_007 | B8: نسبة العقود التأجيرية المربوطة برخص السكن الجماعي | C8: g2 | D8: الهدف الثاني | E8: 0 | F8: 0.35 | G8: 1 | H8: نسبة | I8: نسبة | J8: الأعلى_أفضل | K8: أغسطس 2026 | L8: تجريبي | M8: غير محدد / يحتاج تحديث | N8: خطة العمل V.1.0.0 | O8: أولي | P8: خط الأساس والمستهدف من خطة العمل؛ جهة القيم الحالية غير محددة | Q8: خط الأساس والمستهدف من خطة العمل؛ القيمة الحالية تقديرية وتُستبدل بالفعلية
A9: kpi_008 | B9: نسبة امتثال المساكن الجماعية للأفراد | C9: g3 | D9: الهدف الثالث | E9: 0.15 | F9: 0.21 | G9: 0.3 | H9: نسبة | I9: نسبة | J9: الأعلى_أفضل | K9: أغسطس 2026 | L9: تجريبي | M9: غير محدد / يحتاج تحديث | N9: خطة العمل V.1.0.0 | O9: أولي | P9: خط الأساس والمستهدف من خطة العمل؛ جهة القيم الحالية غير محددة | Q9: خط الأساس والمستهدف من خطة العمل؛ القيمة الحالية تقديرية وتُستبدل بالفعلية
A10: kpi_009 | B10: نسبة اكتمال تطبيق النموذج التشغيلي المستهدف | C10: g4 | D10: الممكن | E10: 0 | F10: 0.4 | G10: 1 | H10: نسبة | I10: نسبة | J10: الأعلى_أفضل | K10: أغسطس 2026 | L10: تجريبي | M10: غير محدد / يحتاج تحديث | N10: خطة العمل V.1.0.0 | O10: أولي | P10: خط الأساس والمستهدف من خطة العمل؛ جهة القيم الحالية غير محددة | Q10: خط الأساس والمستهدف من خطة العمل؛ القيمة الحالية تقديرية وتُستبدل بالفعلية
A11: kpi_010 | B11: نسبة مؤشرات الأداء المتوافقة مع خطة إدارة الأداء | C11: g4 | D11: الممكن | E11: 0 | F11: 0.5 | G11: 1 | H11: نسبة | I11: نسبة | J11: الأعلى_أفضل | K11: أغسطس 2026 | L11: تجريبي | M11: غير محدد / يحتاج تحديث | N11: خطة العمل V.1.0.0 | O11: أولي | P11: خط الأساس والمستهدف من خطة العمل؛ جهة القيم الحالية غير محددة | Q11: خط الأساس والمستهدف من خطة العمل؛ القيمة الحالية تقديرية وتُستبدل بالفعلية
A12: kpi_011 | B12: نسبة أتمتة العمليات في منظومة السكن الجماعي | C12: g4 | D12: الممكن | E12: 0 | F12: 0.45 | G12: 1 | H12: نسبة | I12: نسبة | J12: الأعلى_أفضل | K12: أغسطس 2026 | L12: تجريبي | M12: غير محدد / يحتاج تحديث | N12: خطة العمل V.1.0.0 | O12: أولي | P12: خط الأساس والمستهدف من خطة العمل؛ جهة القيم الحالية غير محددة | Q12: خط الأساس والمستهدف من خطة العمل؛ القيمة الحالية تقديرية وتُستبدل بالفعلية
A13: kpi_012 | B13: نسبة تفعيل قنوات التواصل مع الجمهور المستهدف | C13: g4 | D13: الممكن | E13: 0 | F13: 0.6 | G13: 1 | H13: نسبة | I13: نسبة | J13: الأعلى_أفضل | K13: أغسطس 2026 | L13: تجريبي | M13: غير محدد / يحتاج تحديث | N13: خطة العمل V.1.0.0 | O13: أولي | P13: خط الأساس والمستهدف من خطة العمل؛ جهة القيم الحالية غير محددة | Q13: خط الأساس والمستهدف من خطة العمل؛ القيمة الحالية تقديرية وتُستبدل بالفعلية
... A15: kpi_014 | B15: نسبة طلبات السكن المحفزة للسكن قرب العمل | C15: g1 | D15: الهدف الأول | E15: 0 | F15: 0.3 | G15: 1 | H15: نسبة | I15: نسبة | J15: الأعلى_أفضل | K15: أغسطس 2026 | L15: تجريبي | M15: غير محدد / يحتاج تحديث | N15: خطة العمل V.1.0.0 | O15: أولي | P15: خط الأساس والمستهدف من خطة العمل؛ جهة القيم الحالية غير محددة | Q15: خط الأساس والمستهدف من خطة العمل؛ القيمة الحالية تقديرية وتُستبدل بالفعلية

Sheet 17_تعريفات_ومراجع
B1: الأهداف
B2: goal_id | C2: الاسم | D2: الوصف
B3: g1 | C3: الهدف الأول | D3: زيادة المعروض المرخص
B4: g2 | C4: الهدف الثاني | D4: سد الفجوات التنظيمية
B5: g3 | C5: الهدف الثالث | D5: تحسين آليات الرقابة
B6: g4 | C6: الممكن | D6: الحوكمة والنموذج التشغيلي
B8: القطاعات
B9: sector_id | C9: الاسم
B10: sector_north | C10: قطاع الشمال
B11: sector_east | C11: قطاع الشرق
B12: sector_center | C12: قطاع الوسط
B13: sector_west | C13: قطاع الغرب
B14: sector_south | C14: قطاع الجنوب
B15: sector_unassigned | C15: غير مصنف قطاعياً
B17: حالات المبادرات
B18: status_id | C18: الاسم_المعروض
B19: st_done | C19: منجزة
B20: st_run | C20: جاري العمل
B21: st_late | C21: متأخرة
B22: st_wait | C22: لم تبدأ بعد
B24: أنواع المساكن
B25: housing_type_id | C25: الاسم | D25: icon_key
B26: housing_compound | C26: مجمع سكني | D26: compound
B27: housing_building | C27: مبنى سكني | D27: building
B28: housing_cabins | C28: كبائن متنقلة | D28: cabins
B30: اتجاه المؤشر
B31: direction_id | C31: الاسم
B32: dir_higher | C32: الأعلى_أفضل
B33: dir_lower | C33: الأقل_أفضل
B35: حالة المصدر
B36: source_status_id | C36: الاسم
B37: ss_approved | C37: معتمد
B38: ss_prelim | C38: أولي
B39: ss_review | C39: يحتاج مراجعة
B40: ss_unknown | C40: غير محدد
B42: الجهات المصدرة المعروفة حتى الآن
B43: entity_id | C43: الاسم | D43: نطاقها
B44: ent_licensing_admin | C44: الإدارة العامة للتراخيص | D44: رخص البناء فقط
B45: ent_tbd | C45: غير محدد / يحتاج تحديث | D45: كل ما لم تحدد جهته بعد
B47: أعلام جودة البيانات
...

Sheet 18_الرقابة_الشهرية
A1: month_id | B1: الشهر | C1: التاريخ | D1: الزيارات_الرقابية | E1: المخالفات | F1: جودة_البيانات | G1: الجهة_المصدرة_للبيانات | H1: المصدر | I1: حالة_المصدر | J1: ملاحظات_المصدر | K1: ملاحظات
A2: m2025_09 | B2: سبتمبر 2025 | C2: 45901 | D2: 1548 | E2: 292 | F2: يحتاج مراجعة | G2: غير محدد / يحتاج تحديث | I2: غير محدد
A3: m2025_10 | B3: أكتوبر 2025 | C3: 45931 | D3: 1504 | E3: 288 | F3: يحتاج مراجعة
A4: m2025_11 | B4: نوفمبر 2025 | C4: 45962 | D4: 1601 | E4: 293 | F4: يحتاج مراجعة
A5: m2025_12 | B5: ديسمبر 2025 | C5: 45992 | D5: 1580 | E5: 279 | F5: يحتاج مراجعة
A6: m2026_01 | B6: يناير 2026 | C6: 46023 | D6: 1609 | E6: 292 | F6: يحتاج مراجعة
A7: m2026_02 | B7: فبراير 2026 | C7: 46054 | D7: 1654 | E7: 304 | F7: يحتاج مراجعة
A8: m2026_03 | B8: مارس 2026 | C8: 46082 | D8: 1736 | E8: 316 | F8: يحتاج مراجعة
A9: m2026_04 | B9: أبريل 2026 | C9: 46113 | D9: 1755 | E9: 309 | F9: يحتاج مراجعة
A10: m2026_05 | B10: مايو 2026 | C10: 46143 | D10: 1800 | E10: 310 | F10: يحتاج مراجعة
A11: m2026_06 | B11: يونيو 2026 | C11: 46174 | D11: 1747 | E11: 300 | F11: يحتاج مراجعة
A12: m2026_07 | B12: يوليو 2026 | C12: 46204 | D12: 1558 | E12: 317 | F12: يحتاج مراجعة
A13: m2026_08 | B13: أغسطس 2026 | C13: 46235 | D13: 1559 | E13: 317 | F13: يحتاج مراجعة
B15: الإجمالي (تحقق) | D15: =SUM(D2:D13) -> 19651 | E15: =SUM(E2:E13) -> 3617 | K15: يجب أن يطابق مجموع القطاعات في ورقة 11

Sheet 19_مصادر_البيانات
A1: dataset_id | B1: البند | C1: القسم_في_اللوحة | D1: الورقة/العمود | E1: الجهة_المصدرة_للبيانات | F1: المصدر | G1: حالة_المصدر | H1: ملاحظات_المصدر
A2: ds_building_lic | B2: رخص البناء (خط الأساس والشهري والقطاعي) | C2: التراخيص | D2: 06 و07 (أعمدة البناء) و08 (عمود رخص_البناء) | E2: الإدارة العامة للتراخيص | G2: أولي | H2: الجهة الوحيدة المؤكدة حتى الآن — مسؤولة عن رخص البناء فقط
A3: ds_operational_lic | B3: الرخص التشغيلية (خط الأساس والشهري والقطاعي) | C3: التراخيص | D3: 06 و07 (أعمدة التشغيلية) و08 (عمود الرخص_التشغيلية) | E3: غير محدد / يحتاج تحديث | G3: غير محدد | H3: لا تُنسب للإدارة العامة للتراخيص رغم ظهورها في قسم التراخيص
A4: ds_capacity | B4: الطاقة الاستيعابية (وكل مشتقاتها) | C4: التراخيص / العرض والطلب | D4: 06 و07 (أعمدة الطاقة) و08 و03 | E4: غير محدد / يحتاج تحديث | G4: غير محدد | H4: مرتبطة بالرخص التشغيلية — جهتها تحتاج تحديداً
A5: ds_housing_types | B5: أنواع المساكن التشغيلية | C5: التراخيص | D5: 09 | E5: غير محدد / يحتاج تحديث | G5: غير محدد | H5: بيانات تشغيلية — لا تُنسب للإدارة العامة للتراخيص
A6: ds_demand | B6: الطلب وتركيبته (الإجمالي، الياقات، القطاعات، الأنشطة) | C6: العرض والطلب | D6: 03 و04 و05 | E6: غير محدد / يحتاج تحديث | G6: غير محدد
A7: ds_control | B7: الرقابة (المراقبون، الزيارات، المخالفات، الامتثال) | C7: الرقابة | D7: 10 و11 و12 و18 | E7: غير محدد / يحتاج تحديث | G7: غير محدد
A8: ds_neighborhoods | B8: سجل الأحياء | C8: الرقابة / التراخيص | D8: 13 | E8: غير محدد / يحتاج تحديث | G8: غير محدد | H8: بيانات عينة لم تُحدّث في المسودة الأولى
A9: ds_initiatives | B9: المبادرات وخطتها التنفيذية | C9: المبادرات | D9: 14 و15 | E9: غير محدد / يحتاج تحديث | G9: غير محدد
A10: ds_kpi_targets | B10: مؤشرات الأداء: خط الأساس والمستهدفات | C10: مؤشرات الأداء | D10: 16 (عمودا خط_الأساس والمستهدف) | E10: غير محدد / يحتاج تحديث | F10: خطة العمل V.1.0.0 | G10: أولي | H10: المصدر وثيقة خطة العمل — الجهة المنتجة تحتاج تحديداً
A11: ds_kpi_currents | B11: مؤشرات الأداء: القيم الحالية | C11: مؤشرات الأداء | D11: 16 (عمود القيمة_الحالية) | E11: غير محدد / يحتاج تحديث | G11: غير محدد | H11: قيم تقديرية للعرض حتى تصل القيم الفعلية من جهاتها
